<?xml version="1.0"?>
<robot xmlns:xacro="http://ros.org/wiki/xacro">

  <xacro:property name="pi" value="3.14159265" />


  <xacro:macro name="actuated_wheel_link" params="prefix locationprefix">
    <link name="${prefix}${locationprefix}_act_wheel">
      <inertial>
        <origin xyz="0 0 0" rpy="${0.5 * pi} ${0.5 * pi} 0" />
        <mass value="1.0" />
        <inertia
            ixx="0.0021285829616"
            ixy="0"
            ixz="0"
            iyy="0.0011566983393"
            iyz="0"
            izz="0.0011566983393" />
      </inertial>
      <visual>
        <origin xyz="0 0 0" rpy="0 0 0" />
        <geometry>
          <mesh filename="package://mobipick_description/meshes/mir_100/visual/actuated_wheel.stl" />
        </geometry>
        <material name="">
          <color rgba="1.0 0.0 0.0 1" />
        </material>
      </visual>
      <collision>
        <origin xyz="0 0 0" rpy="0 0 0" />
        <geometry>
          <mesh filename="package://mobipick_description/meshes/mir_100/collision/actuated_wheel.stl" />
        </geometry>
      </collision>
    </link>
  </xacro:macro>


  <xacro:macro name="caster_wheel_links" params="prefix locationprefix">
    <link name="${prefix}${locationprefix}_caster_wheel_base">
      <inertial>
        <origin xyz="0 0 -0.042500000044" rpy="${0.5 * pi} ${24 / 180 * pi} ${1.5 * pi}" />
        <mass value="0.3097539019" />
        <inertia
            ixx="0.0005844517978"
            ixy="0"
            ixz="0"
            iyy="0.00052872551237"
            iyz="0"
            izz="0.00017923555074" />
      </inertial>
      <visual>
        <origin xyz="0 0 0" rpy="0 0 0" />
        <geometry>
          <mesh filename="package://mobipick_description/meshes/mir_100/visual/caster_wheel_base.stl" />
        </geometry>
        <material name="">
          <color rgba="0.4 0.4 0.4 1" />
        </material>
      </visual>
      <collision>
        <origin xyz="0 0 0" rpy="0 0 0" />
        <geometry>
          <mesh filename="package://mobipick_description/meshes/mir_100/collision/caster_wheel_base.stl" />
        </geometry>
      </collision>
    </link>
    <link name="${prefix}${locationprefix}_caster_wheel">
      <inertial>
        <origin xyz="0 0 0" rpy="${0.5 * pi} ${0.5 * pi} 0" />
        <mass value="1.0" />
        <inertia
            ixx="0.0021285829616"
            ixy="0"
            ixz="0"
            iyy="0.0011566983393"
            iyz="0"
            izz="0.0011566983393" />
      </inertial>
      <visual>
        <origin xyz="0 0 0" rpy="0 0 0" />
        <geometry>
          <mesh filename="package://mobipick_description/meshes/mir_100/visual/caster_wheel.stl" />
        </geometry>
        <material name="">
          <color rgba="0.4 0.4 0.4 1" />
        </material>
      </visual>
      <collision>
        <origin xyz="0 0 0" rpy="0 0 0" />
        <geometry>
          <mesh filename="package://mobipick_description/meshes/mir_100/collision/caster_wheel.stl" />
        </geometry>
      </collision>
    </link>
  </xacro:macro>


  <xacro:macro name="actuated_wheel_joint" params="prefix locationprefix locationright">
    <joint name="${prefix}base_${locationprefix}_act_wheel_joint" type="continuous">
      <origin xyz="-0.037646 ${-0.222604 * locationright} 0.0625" rpy="0 0 0" />
      <parent link="${prefix}base" />
      <child link="${prefix}${locationprefix}_act_wheel" />
      <axis xyz="0 1 0" />
    </joint>
  </xacro:macro>


  <xacro:macro name="front_caster_wheel_joints" params="prefix locationprefix locationright">
    <joint name="${prefix}base_front_${locationprefix}_wheel_base_joint" type="continuous">
      <origin xyz="0.3037 ${-0.203 * locationright} 0.1565" rpy="0 0 0" />
      <parent link="${prefix}base" />
      <child link="${prefix}front_${locationprefix}_caster_wheel_base" />
      <axis xyz="0 0 1" />
    </joint>
    <joint name="${prefix}base_front_${locationprefix}_wheel_joint" type="continuous">
      <origin xyz="-0.0382 0 -0.094" rpy="0 0 0" />
      <parent link="${prefix}front_${locationprefix}_caster_wheel_base" />
      <child link="${prefix}front_${locationprefix}_caster_wheel" />
      <axis xyz="0 1 0" />
    </joint>
  </xacro:macro>

  <xacro:macro name="back_caster_wheel_joints" params="prefix locationprefix locationright">
    <joint name="${prefix}base_back_${locationprefix}_wheel_base_joint" type="continuous">
      <origin xyz="-0.3078 ${-0.203 * locationright} 0.1565" rpy="0 0 0" />
      <parent link="${prefix}base" />
      <child link="${prefix}back_${locationprefix}_caster_wheel_base" />
      <axis xyz="0 0 1" />
    </joint>
    <joint name="${prefix}base_back_${locationprefix}_wheel_joint" type="continuous">
      <origin xyz="-0.0382 0 -0.094" rpy="0 0 0" />
      <parent link="${prefix}back_${locationprefix}_caster_wheel_base" />
      <child link="${prefix}back_${locationprefix}_caster_wheel" />
      <axis xyz="0 1 0" />
    </joint>
  </xacro:macro>

  <xacro:macro name="mir_100" params="prefix">

    <link name="${prefix}base">
      <inertial>
        <origin xyz="0 -0.2528237011 0.1623852639" rpy="${0.5 * pi} ${0.5 * pi} 0" />
        <mass value="60.0" />
        <inertia
            ixx="2.104161731"
            ixy="0"
            ixz="0"
            iyy="1.927704596"
            iyz="0"
            izz="0.194324673" />
      </inertial>
      <visual>
        <origin xyz="0 0 0" rpy="0 0 0" />
        <geometry>
          <mesh filename="package://mobipick_description/meshes/mir_100/visual/mir_100_base.stl" />
        </geometry>
        <material name="">
          <color rgba="0.8 0.8 0.8 1" />
        </material>
      </visual>
      <collision>
        <origin xyz="0 0 0" rpy="0 0 0" />
        <geometry>
          <mesh filename="package://mobipick_description/meshes/mir_100/collision/mir_100_base.stl" />
        </geometry>
      </collision>
    </link>

    <xacro:actuated_wheel_link prefix="${prefix}" locationprefix="left"/>
    <xacro:actuated_wheel_link prefix="${prefix}" locationprefix="right"/>
    <xacro:caster_wheel_links prefix="${prefix}" locationprefix="front_left"/>
    <xacro:caster_wheel_links prefix="${prefix}" locationprefix="front_right"/>
    <xacro:caster_wheel_links prefix="${prefix}" locationprefix="back_left"/>
    <xacro:caster_wheel_links prefix="${prefix}" locationprefix="back_right"/>

    <xacro:actuated_wheel_joint prefix="${prefix}" locationprefix="left" locationright="-1"/>
    <xacro:actuated_wheel_joint prefix="${prefix}" locationprefix="right" locationright="1"/>
    <xacro:front_caster_wheel_joints prefix="${prefix}" locationprefix="left" locationright="-1"/>
    <xacro:front_caster_wheel_joints prefix="${prefix}" locationprefix="right" locationright="1"/>
    <xacro:back_caster_wheel_joints prefix="${prefix}" locationprefix="left" locationright="-1"/>
    <xacro:back_caster_wheel_joints prefix="${prefix}" locationprefix="right" locationright="1"/>


    <joint name="${prefix}base_surface_joint" type="fixed">
      <origin xyz="0 0 0.352" rpy="0 0 0" />
      <parent link="${prefix}base" />
      <child link="${prefix}surface" />
      <axis xyz="0 0 1" />
    </joint>

    <link name="${prefix}surface"/>

  </xacro:macro>
</robot>
